<!--URDF generated by ONSHAPE BY PTC INC, 1.216-->
<robot name="pkg_20_gripper_assembly">
    <link name="arduino_robot_arm_3d_fabri_creator_10">
        <inertial>
            <mass value="7.32325e-06" />
            <origin xyz="-0.013857 -0.0266092 0.0104888" rpy="-0.500173 0.290054 -0.0731095" />
            <inertia ixx="1.63602e-09" ixy="-8.58689e-10" ixz="4.70865e-10" iyy="1.16121e-09" iyz="6.09712e-10" izz="1.99458e-09" />
        </inertial>
        <visual>
            <origin xyz="0.109369 -0.274088 -0.0361001" rpy="-0.500173 0.290054 -0.0731095" />
            <geometry>
                <mesh filename="package://pkg_20_gripper_assembly/meshes/Arduino_Robot_Arm_3D_FABRI_creator_10.stl" scale="1 1 1" />
            </geometry>
            <material name="1.000000_1.000000_1.000000_0.000000_0.000000">
                <color rgba="1 1 1 1" />
            </material>
        </visual>
    </link>
    <link name="arduino_robot_arm_3d_fabri_creator_10__1__loop_closure">
        <inertial>
            <mass value="1e-09" />
            <origin xyz="0 0 0" rpy="0 -0 0" />
            <inertia ixx="4e-14" ixy="0" ixz="0" iyy="4e-14" iyz="0" izz="4e-14" />
        </inertial>
    </link>
    <link name="arduino_robot_arm_3d_fabri_creator_11">
        <inertial>
            <mass value="2.64161e-06" />
            <origin xyz="-0.00427212 -0.00307281 -0.00279136" rpy="0 -0 0" />
            <inertia ixx="3.76352e-10" ixy="-1.13752e-10" ixz="-7.075e-11" iyy="2.64701e-10" iyz="-1.12982e-10" izz="2.6047e-10" />
        </inertial>
        <visual>
            <origin xyz="0.120692 -0.255653 -0.0807336" rpy="0 -0 0" />
            <geometry>
                <mesh filename="package://pkg_20_gripper_assembly/meshes/Arduino_Robot_Arm_3D_FABRI_creator_11.stl" scale="1 1 1" />
            </geometry>
            <material name="1.000000_1.000000_1.000000_0.000000_0.000000">
                <color rgba="1 1 1 1" />
            </material>
        </visual>
    </link>
    <link name="arduino_robot_arm_3d_fabri_creator_6">
        <inertial>
            <mass value="7.29113e-06" />
            <origin xyz="-0.0137623 -0.0264022 -0.0111357" rpy="0.47902 -0.278503 -0.0698324" />
            <inertia ixx="1.64196e-09" ixy="-8.44834e-10" ixz="-4.90911e-10" iyy="1.186e-09" iyz="-6.32545e-10" izz="1.96062e-09" />
        </inertial>
        <visual>
            <origin xyz="0.160764 -0.190973 -0.120593" rpy="0.47902 -0.278503 -0.0698324" />
            <geometry>
                <mesh filename="package://pkg_20_gripper_assembly/meshes/Arduino_Robot_Arm_3D_FABRI_creator_6.stl" scale="1 1 1" />
            </geometry>
            <material name="1.000000_1.000000_1.000000_0.000000_0.000000">
                <color rgba="1 1 1 1" />
            </material>
        </visual>
    </link>
    <link name="arduino_robot_arm_3d_fabri_creator_6__1__loop_closure">
        <inertial>
            <mass value="1e-09" />
            <origin xyz="0 0 0" rpy="0 -0 0" />
            <inertia ixx="4e-14" ixy="0" ixz="0" iyy="4e-14" iyz="0" izz="4e-14" />
        </inertial>
    </link>
    <link name="arduino_robot_arm_3d_fabri_creator_7">
        <inertial>
            <mass value="7.98762e-07" />
            <origin xyz="-0.0083912 -0.0096729 -0.00895951" rpy="0 -0 0" />
            <inertia ixx="8.54958e-11" ixy="-3.03463e-11" ixz="-2.47973e-11" iyy="5.57727e-11" iyz="-3.97447e-11" izz="6.971e-11" />
        </inertial>
        <visual>
            <origin xyz="0.131266 -0.238599 -0.088565" rpy="0 -0 0" />
            <geometry>
                <mesh filename="package://pkg_20_gripper_assembly/meshes/Arduino_Robot_Arm_3D_FABRI_creator_7.stl" scale="1 1 1" />
            </geometry>
            <material name="1.000000_1.000000_1.000000_0.000000_0.000000">
                <color rgba="1 1 1 1" />
            </material>
        </visual>
    </link>
    <link name="arduino_robot_arm_3d_fabri_creator_7_1">
        <inertial>
            <mass value="7.98762e-07" />
            <origin xyz="-0.0083912 -0.0096729 -0.00895951" rpy="0 -0 0" />
            <inertia ixx="8.54958e-11" ixy="-3.03463e-11" ixz="-2.47973e-11" iyy="5.57727e-11" iyz="-3.97447e-11" izz="6.971e-11" />
        </inertial>
        <visual>
            <origin xyz="0.131266 -0.238599 -0.088565" rpy="0 -0 0" />
            <geometry>
                <mesh filename="package://pkg_20_gripper_assembly/meshes/Arduino_Robot_Arm_3D_FABRI_creator_7.stl" scale="1 1 1" />
            </geometry>
            <material name="1.000000_1.000000_1.000000_0.000000_0.000000">
                <color rgba="1 1 1 1" />
            </material>
        </visual>
    </link>
    <link name="arduino_robot_arm_3d_fabri_creator_8">
        <inertial>
            <mass value="2.56586e-06" />
            <origin xyz="-0.00432821 -0.00318931 0.00274923" rpy="0 -0 0" />
            <inertia ixx="3.74609e-10" ixy="-1.15487e-10" ixz="6.9099e-11" iyy="2.59765e-10" iyz="1.12068e-10" izz="2.64793e-10" />
        </inertial>
        <visual>
            <origin xyz="0.120755 -0.255426 -0.107633" rpy="0 -0 0" />
            <geometry>
                <mesh filename="package://pkg_20_gripper_assembly/meshes/Arduino_Robot_Arm_3D_FABRI_creator_8.stl" scale="1 1 1" />
            </geometry>
            <material name="1.000000_1.000000_1.000000_0.000000_0.000000">
                <color rgba="1 1 1 1" />
            </material>
        </visual>
    </link>
    <link name="arduino_robot_arm_3d_fabri_creator_9">
        <inertial>
            <mass value="1.55679e-05" />
            <origin xyz="-0.030386 -0.0110514 0.00587171" rpy="0 -0 0" />
            <inertia ixx="5.33351e-09" ixy="-3.10318e-09" ixz="1.00142e-09" iyy="5.23651e-09" iyz="1.00447e-09" izz="7.19781e-09" />
        </inertial>
        <visual>
            <origin xyz="0.0729913 -0.272714 -0.0859889" rpy="0 -0 0" />
            <geometry>
                <mesh filename="package://pkg_20_gripper_assembly/meshes/Arduino_Robot_Arm_3D_FABRI_creator_9.stl" scale="1 1 1" />
            </geometry>
            <material name="1.000000_1.000000_1.000000_0.000000_0.000000">
                <color rgba="1 1 1 1" />
            </material>
        </visual>
    </link>
    <link name="root" />
    <joint name="fastened_1" type="fixed">
        <origin xyz="2.77556e-17 2.77556e-17 0" rpy="-0.00473492 -3.83331e-15 -1.01482" />
        <axis xyz="0.849388 -0.527763 -0.00249893" />
        <parent link="root" />
        <child link="arduino_robot_arm_3d_fabri_creator_9" />
    </joint>
    <joint name="revolute_1" type="continuous">
        <origin xyz="-0.0447283 -0.0189072 -0.00526405" rpy="-0.495392 0.287647 -0.0717603" />
        <axis xyz="0.849388 -0.527763 -0.00249893" />
        <parent link="arduino_robot_arm_3d_fabri_creator_9" />
        <child link="arduino_robot_arm_3d_fabri_creator_11" />
    </joint>
    <joint name="revolute_2" type="continuous">
        <origin xyz="-0.0447907 -0.019135 0.0216349" rpy="0.49577 -0.286955 -0.074551" />
        <axis xyz="0.849388 -0.527763 -0.00249893" />
        <parent link="arduino_robot_arm_3d_fabri_creator_9" />
        <child link="arduino_robot_arm_3d_fabri_creator_8" />
    </joint>
    <joint name="revolute_3" type="continuous">
        <origin xyz="-0.0132752 -0.0214485 0.0175867" rpy="4.84612e-14 -2.87409e-14 -1.11022e-15" />
        <axis xyz="-0.849388 0.527763 0.00249893" />
        <parent link="arduino_robot_arm_3d_fabri_creator_8" />
        <child link="arduino_robot_arm_3d_fabri_creator_10" />
    </joint>
    <joint name="revolute_4" type="continuous">
        <origin xyz="-0.0131594 -0.0210932 -0.0180961" rpy="9.10383e-15 -6.18949e-15 5.68989e-16" />
        <axis xyz="-0.849388 0.527763 0.00249893" />
        <parent link="arduino_robot_arm_3d_fabri_creator_11" />
        <child link="arduino_robot_arm_3d_fabri_creator_6" />
    </joint>
    <joint name="revolute_5" type="continuous">
        <origin xyz="-0.0553021 -0.035962 0.00256731" rpy="-0.500387 0.290161 -0.0731699" />
        <axis xyz="0.849388 -0.527763 -0.00249893" />
        <parent link="arduino_robot_arm_3d_fabri_creator_9" />
        <child link="arduino_robot_arm_3d_fabri_creator_7_1" />
    </joint>
    <joint name="revolute_6_loop_closure" type="continuous">
        <origin xyz="-0.0133848 -0.0214568 -0.017929" rpy="-3.96905e-15 1.04083e-15 1.72085e-15" />
        <axis xyz="-0.849388 0.527763 0.00249893" />
        <parent link="arduino_robot_arm_3d_fabri_creator_7_1" />
        <child link="arduino_robot_arm_3d_fabri_creator_6__1__loop_closure" />
    </joint>
    <joint name="revolute_7" type="continuous">
        <origin xyz="-0.0553253 -0.0360466 0.0125669" rpy="-0.589255 0.333084 -0.100203" />
        <axis xyz="0.849388 -0.527763 -0.00249893" />
        <parent link="arduino_robot_arm_3d_fabri_creator_9" />
        <child link="arduino_robot_arm_3d_fabri_creator_7" />
    </joint>
    <joint name="revolute_8_loop_closure" type="continuous">
        <origin xyz="-0.0133848 -0.0214568 -0.017929" rpy="0.584831 -0.329854 -0.101845" />
        <axis xyz="-0.849388 0.527763 0.00249893" />
        <parent link="arduino_robot_arm_3d_fabri_creator_7" />
        <child link="arduino_robot_arm_3d_fabri_creator_10__1__loop_closure" />
    </joint>
</robot>
