<!--URDF generated by ONSHAPE BY PTC INC, 1.216-->
<robot name="pkg_21_main_assembly">
    <link name="20_gripper_assembly__1_" />
    <link name="arduino_robot_arm_3d_fabri_creator_10">
        <inertial>
            <mass value="7.32325e-06" />
            <origin xyz="-0.0141172 -0.0269344 -0.00923709" rpy="0.0517619 -0.0321311 -0.000984114" />
            <inertia ixx="1.5603e-09" ixy="-9.62701e-10" ixz="-2.79917e-10" iyy="1.02048e-09" iyz="-3.80836e-10" izz="2.21103e-09" />
        </inertial>
        <visual>
            <origin xyz="0.138143 -0.227321 -0.132781" rpy="0.0517619 -0.0321311 -0.000984114" />
            <geometry>
                <mesh filename="package://pkg_21_main_assembly/meshes/Arduino_Robot_Arm_3D_FABRI_creator_10.stl" scale="1 1 1" />
            </geometry>
            <material name="1.000000_1.000000_1.000000_0.000000_0.000000">
                <color rgba="1 1 1 1" />
            </material>
        </visual>
    </link>
    <link name="arduino_robot_arm_3d_fabri_creator_10__1__loop_closure">
        <inertial>
            <mass value="1e-09" />
            <origin xyz="0 0 0" rpy="0 -0 0" />
            <inertia ixx="4e-14" ixy="0" ixz="0" iyy="4e-14" iyz="0" izz="4e-14" />
        </inertial>
    </link>
    <link name="arduino_robot_arm_3d_fabri_creator_11">
        <inertial>
            <mass value="2.64161e-06" />
            <origin xyz="-0.00427212 -0.00307281 -0.00279136" rpy="0 -0 0" />
            <inertia ixx="3.76352e-10" ixy="-1.13752e-10" ixz="-7.075e-11" iyy="2.64701e-10" iyz="-1.12982e-10" izz="2.6047e-10" />
        </inertial>
        <visual>
            <origin xyz="0.120692 -0.255653 -0.0807336" rpy="0 -0 0" />
            <geometry>
                <mesh filename="package://pkg_21_main_assembly/meshes/Arduino_Robot_Arm_3D_FABRI_creator_11.stl" scale="1 1 1" />
            </geometry>
            <material name="1.000000_1.000000_1.000000_0.000000_0.000000">
                <color rgba="1 1 1 1" />
            </material>
        </visual>
    </link>
    <link name="arduino_robot_arm_3d_fabri_creator_6">
        <inertial>
            <mass value="7.29113e-06" />
            <origin xyz="-0.0142686 -0.0273067 0.00782507" rpy="-0.050656 0.0314562 -0.000647925" />
            <inertia ixx="1.54939e-09" ixy="-9.80687e-10" ixz="2.2596e-10" iyy="9.90478e-10" iyz="3.1015e-10" izz="2.24871e-09" />
        </inertial>
        <visual>
            <origin xyz="0.132038 -0.237517 -0.0548651" rpy="-0.050656 0.0314562 -0.000647925" />
            <geometry>
                <mesh filename="package://pkg_21_main_assembly/meshes/Arduino_Robot_Arm_3D_FABRI_creator_6.stl" scale="1 1 1" />
            </geometry>
            <material name="1.000000_1.000000_1.000000_0.000000_0.000000">
                <color rgba="1 1 1 1" />
            </material>
        </visual>
    </link>
    <link name="arduino_robot_arm_3d_fabri_creator_6__1__loop_closure">
        <inertial>
            <mass value="1e-09" />
            <origin xyz="0 0 0" rpy="0 -0 0" />
            <inertia ixx="4e-14" ixy="0" ixz="0" iyy="4e-14" iyz="0" izz="4e-14" />
        </inertial>
    </link>
    <link name="arduino_robot_arm_3d_fabri_creator_7">
        <inertial>
            <mass value="7.98762e-07" />
            <origin xyz="-0.0083912 -0.0096729 -0.00895951" rpy="0 -0 0" />
            <inertia ixx="8.54958e-11" ixy="-3.03463e-11" ixz="-2.47973e-11" iyy="5.57727e-11" iyz="-3.97447e-11" izz="6.971e-11" />
        </inertial>
        <visual>
            <origin xyz="0.131266 -0.238599 -0.088565" rpy="0 -0 0" />
            <geometry>
                <mesh filename="package://pkg_21_main_assembly/meshes/Arduino_Robot_Arm_3D_FABRI_creator_7.stl" scale="1 1 1" />
            </geometry>
            <material name="1.000000_1.000000_1.000000_0.000000_0.000000">
                <color rgba="1 1 1 1" />
            </material>
        </visual>
    </link>
    <link name="arduino_robot_arm_3d_fabri_creator_7_1">
        <inertial>
            <mass value="7.98762e-07" />
            <origin xyz="-0.0083912 -0.0096729 -0.00895951" rpy="0 -0 0" />
            <inertia ixx="8.54958e-11" ixy="-3.03463e-11" ixz="-2.47973e-11" iyy="5.57727e-11" iyz="-3.97447e-11" izz="6.971e-11" />
        </inertial>
        <visual>
            <origin xyz="0.131266 -0.238599 -0.088565" rpy="0 -0 0" />
            <geometry>
                <mesh filename="package://pkg_21_main_assembly/meshes/Arduino_Robot_Arm_3D_FABRI_creator_7.stl" scale="1 1 1" />
            </geometry>
            <material name="1.000000_1.000000_1.000000_0.000000_0.000000">
                <color rgba="1 1 1 1" />
            </material>
        </visual>
    </link>
    <link name="arduino_robot_arm_3d_fabri_creator_8">
        <inertial>
            <mass value="2.56586e-06" />
            <origin xyz="-0.00432821 -0.00318931 0.00274923" rpy="0 -0 0" />
            <inertia ixx="3.74609e-10" ixy="-1.15487e-10" ixz="6.9099e-11" iyy="2.59765e-10" iyz="1.12068e-10" izz="2.64793e-10" />
        </inertial>
        <visual>
            <origin xyz="0.120755 -0.255426 -0.107633" rpy="0 -0 0" />
            <geometry>
                <mesh filename="package://pkg_21_main_assembly/meshes/Arduino_Robot_Arm_3D_FABRI_creator_8.stl" scale="1 1 1" />
            </geometry>
            <material name="1.000000_1.000000_1.000000_0.000000_0.000000">
                <color rgba="1 1 1 1" />
            </material>
        </visual>
    </link>
    <link name="arduino_robot_arm_3d_fabri_creator_9">
        <inertial>
            <mass value="1.55679e-05" />
            <origin xyz="-0.00362846 -0.0241572 0.00182264" rpy="-0.00316495 -0.00467795 0.654934" />
            <inertia ixx="8.29356e-09" ixy="-7.61715e-10" ixz="1.88314e-10" iyy="2.27342e-09" iyz="1.40067e-09" izz="7.20085e-09" />
        </inertial>
        <visual>
            <origin xyz="0.238252 -0.168681 -0.0887248" rpy="-0.00316495 -0.00467795 0.654934" />
            <geometry>
                <mesh filename="package://pkg_21_main_assembly/meshes/Arduino_Robot_Arm_3D_FABRI_creator_9.stl" scale="1 1 1" />
            </geometry>
            <material name="1.000000_1.000000_1.000000_0.000000_0.000000">
                <color rgba="1 1 1 1" />
            </material>
        </visual>
    </link>
    <link name="part_1">
        <inertial>
            <mass value="6.42811e-05" />
            <origin xyz="0.06 -1.95201e-12 0.00781766" rpy="0 -0 0" />
            <inertia ixx="9.2905e-09" ixy="0" ixz="0" iyy="1.03844e-07" iyz="0" izz="1.08717e-07" />
        </inertial>
        <visual>
            <origin xyz="0.06 -1.24521e-17 0" rpy="0 -0 0" />
            <geometry>
                <mesh filename="package://pkg_21_main_assembly/meshes/Part_1.stl" scale="1 1 1" />
            </geometry>
            <material name="0.301961_0.301961_0.301961_0.000000_0.000000">
                <color rgba="0.301961 0.301961 0.301961 1" />
            </material>
        </visual>
    </link>
    <link name="part_1_1">
        <inertial>
            <mass value="9.20937e-05" />
            <origin xyz="-0.000213347 -0.00117911 0.0212615" rpy="0 -0 0" />
            <inertia ixx="1.29794e-07" ixy="-7.23584e-10" ixz="-2.44873e-10" iyy="1.23971e-07" iyz="-3.47683e-09" izz="2.01485e-07" />
        </inertial>
        <visual>
            <origin xyz="0 -3.71221e-18 0" rpy="0 -0 0" />
            <geometry>
                <mesh filename="package://pkg_21_main_assembly/meshes/Part_1_1.stl" scale="1 1 1" />
            </geometry>
            <material name="0.301961_0.290196_0.262745_0.000000_0.000000">
                <color rgba="0.301961 0.290196 0.262745 1" />
            </material>
        </visual>
    </link>
    <link name="part_1_2">
        <inertial>
            <mass value="9.2706e-05" />
            <origin xyz="-0.0510605 -2.37559e-12 0.0125955" rpy="0 -0 0" />
            <inertia ixx="1.77599e-08" ixy="0" ixz="6.81356e-09" iyy="1.45236e-07" iyz="0" izz="1.53525e-07" />
        </inertial>
        <visual>
            <origin xyz="-0.081 -1.13373e-18 0.008" rpy="0 -0 0" />
            <geometry>
                <mesh filename="package://pkg_21_main_assembly/meshes/Part_1_2.stl" scale="1 1 1" />
            </geometry>
            <material name="0.301961_0.301961_0.301961_0.000000_0.000000">
                <color rgba="0.301961 0.301961 0.301961 1" />
            </material>
        </visual>
    </link>
    <link name="part_1_3">
        <inertial>
            <mass value="7.5729e-05" />
            <origin xyz="0.00627678 -0.00626315 0.0206344" rpy="0 0 -0.269947" />
            <inertia ixx="6.78497e-08" ixy="-2.63013e-09" ixz="-3.69249e-09" iyy="5.35105e-08" iyz="9.8245e-09" izz="5.66708e-08" />
        </inertial>
        <visual>
            <origin xyz="6.12355e-20 2.21306e-19 0" rpy="0 0 -0.269947" />
            <geometry>
                <mesh filename="package://pkg_21_main_assembly/meshes/Part_1_3.stl" scale="1 1 1" />
            </geometry>
            <material name="0.301961_0.301961_0.301961_0.000000_0.000000">
                <color rgba="0.301961 0.301961 0.301961 1" />
            </material>
        </visual>
    </link>
    <link name="root" />
    <joint name="fastened_1" type="fixed">
        <origin xyz="0.0137718 0.00311774 -0.00394181" rpy="-0.00314484 -0.00380237 1.66977" />
        <axis xyz="-0 1 -0" />
        <parent link="arduino_robot_arm_3d_fabri_creator_9" />
        <child link="20_gripper_assembly__1_" />
    </joint>
    <joint name="fastened_1_1" type="fixed">
        <origin xyz="0 2.42764e-19 0" rpy="0 -0 0" />
        <axis xyz="-0 -0 -1" />
        <parent link="root" />
        <child link="part_1_1" />
    </joint>
    <joint name="revolute_1" type="continuous">
        <origin xyz="-0.0101554 -0.0391197 -0.00935517" rpy="0.0485599 -0.0367875 0.654053" />
        <axis xyz="0.849388 -0.527763 -0.00249893" />
        <parent link="arduino_robot_arm_3d_fabri_creator_9" />
        <child link="arduino_robot_arm_3d_fabri_creator_11" />
    </joint>
    <joint name="revolute_1_1" type="revolute">
        <origin xyz="-2.89609e-21 -9.75309e-19 0.054" rpy="-3.03185e-20 -5.97068e-21 5.55112e-17" />
        <axis xyz="0 0 -1" />
        <parent link="part_1_1" />
        <child link="part_1_3" />
        <limit effort="1" velocity="1" lower="-0.269947" upper="2.87165" />
    </joint>
    <joint name="revolute_2" type="continuous">
        <origin xyz="-0.0102178 -0.0393475 0.0175438" rpy="-0.0548804 0.0274342 0.654154" />
        <axis xyz="0.849388 -0.527763 -0.00249893" />
        <parent link="arduino_robot_arm_3d_fabri_creator_9" />
        <child link="arduino_robot_arm_3d_fabri_creator_8" />
    </joint>
    <joint name="revolute_2_1" type="revolute">
        <origin xyz="0.000145616 -0.014473 0.04028" rpy="1.5708 -0.658165 -1.84074" />
        <axis xyz="-0 -0 -1" />
        <parent link="part_1_3" />
        <child link="part_1" />
        <limit effort="1" velocity="1" lower="-2.48343" upper="0.658165" />
    </joint>
    <joint name="revolute_3" type="continuous">
        <origin xyz="-0.0132752 -0.0214485 0.0175867" rpy="5.92755e-15 1.31839e-15 -4.41314e-15" />
        <axis xyz="-0.849388 0.527763 0.00249893" />
        <parent link="arduino_robot_arm_3d_fabri_creator_8" />
        <child link="arduino_robot_arm_3d_fabri_creator_10" />
    </joint>
    <joint name="revolute_3_1" type="revolute">
        <origin xyz="0.12 5.55112e-17 2.1684e-17" rpy="-3.14159 2.00999e-15 -2.86774" />
        <axis xyz="-0 -0 -1" />
        <parent link="part_1" />
        <child link="part_1_2" />
        <limit effort="1" velocity="1" lower="-0.273851" upper="2.86774" />
    </joint>
    <joint name="revolute_4" type="revolute">
        <origin xyz="-0.11575 -8.67362e-17 0.008" rpy="-0.00846785 0.00231945 -1.5708" />
        <axis xyz="-0.00231945 -0.00846773 0.999961" />
        <parent link="part_1_2" />
        <child link="arduino_robot_arm_3d_fabri_creator_9" />
        <limit effort="1" velocity="1" lower="-0.65495" upper="2.48664" />
    </joint>
    <joint name="revolute_4_1" type="continuous">
        <origin xyz="-0.0131594 -0.0210932 -0.0180961" rpy="1.58294e-15 -4.75314e-16 -3.13638e-15" />
        <axis xyz="-0.849388 0.527763 0.00249893" />
        <parent link="arduino_robot_arm_3d_fabri_creator_11" />
        <child link="arduino_robot_arm_3d_fabri_creator_6" />
    </joint>
    <joint name="revolute_5" type="continuous">
        <origin xyz="-0.0081975 -0.0590889 -0.00151942" rpy="0.0485338 -0.0367713 0.654054" />
        <axis xyz="0.849388 -0.527763 -0.00249893" />
        <parent link="arduino_robot_arm_3d_fabri_creator_9" />
        <child link="arduino_robot_arm_3d_fabri_creator_7_1" />
    </joint>
    <joint name="revolute_6_loop_closure" type="continuous">
        <origin xyz="-0.0133848 -0.0214568 -0.017929" rpy="3.2899e-15 -6.35603e-15 -6.10623e-16" />
        <axis xyz="-0.849388 0.527763 0.00249893" />
        <parent link="arduino_robot_arm_3d_fabri_creator_7_1" />
        <child link="arduino_robot_arm_3d_fabri_creator_6__1__loop_closure" />
    </joint>
    <joint name="revolute_7" type="continuous">
        <origin xyz="-0.00822069 -0.0591735 0.00848019" rpy="-1.24066 0.527492 0.273293" />
        <axis xyz="0.849388 -0.527763 -0.00249893" />
        <parent link="arduino_robot_arm_3d_fabri_creator_9" />
        <child link="arduino_robot_arm_3d_fabri_creator_7" />
    </joint>
    <joint name="revolute_8_loop_closure" type="continuous">
        <origin xyz="-0.0133848 -0.0214568 -0.017929" rpy="1.24004 -0.529476 -0.386119" />
        <axis xyz="-0.849388 0.527763 0.00249893" />
        <parent link="arduino_robot_arm_3d_fabri_creator_7" />
        <child link="arduino_robot_arm_3d_fabri_creator_10__1__loop_closure" />
    </joint>
</robot>
